<?xml version="1.0"?>

<robot xmlns:xacro="http://ros.org/wiki/xacro">

  <xacro:macro name="cmanip"
  params="parent *origin">


    <xacro:property name="a1" value="0.122490"/>
    <xacro:property name="a2" value="0.1365"/>
    <xacro:property name="a3" value="0.075511"/>
    <xacro:property name="a4" value="0.072489"/>
    <xacro:property name="d5" value="0.04526"/>
    <xacro:property name="theta1" value="${pi/2}"/>
    <xacro:property name="alpha2" value="${-pi/2}"/>

    <xacro:property name="mass1" value="0.01715"/>
    <xacro:property name="mass2" value="0.10663"/>
    <xacro:property name="mass3" value="0.17449"/>
    <xacro:property name="mass4" value="0.01133"/>
    <xacro:property name="mass5" value="0.08200"/>

    <xacro:property name="rad" value="0.03"/>

    <!--link name="world"></link-->



    <link name='link1'>
      <inertial>
        <mass value="${mass1}" />
        <origin xyz="0.00073 0.06124 -0.00009" rpy="0 0 0"/>
        <inertia ixx = "0.00003618101"	ixy = "-0.00000032742"	ixz = "0.00" iyy = "0.00000866025"	iyz = "0.00"	izz = "0.00003041429"/>
      </inertial>

      <visual>
        <origin xyz="0 0 0" rpy="0 0 0" />
        <geometry>
          <mesh filename="package://aerial_manipulators/meshes/wp_manipulator/link1.dae"
            scale="1 1 1" />
        </geometry>
      </visual>
    </link>



    <link name='link2'>
      <inertial>
        <mass value="${mass2}" />
        <origin xyz="0.0257 0.00004 0" rpy="0 0 0"/>
        <inertia ixx="0.000025414" ixy="0.00000000062" ixz="-0.00000114006" iyy="0.00013446945" iyz="0.00000000001" izz="0.00013233260"/>
      </inertial>

      <visual>
        <origin xyz="0 0 0" rpy="0 0 -${pi / 2}" />
        <geometry>
          <mesh filename="package://aerial_manipulators/meshes/wp_manipulator/link2.dae"
            scale="1 1 1" />
        </geometry>
      </visual>
    </link>


    <link name='link3'>
      <inertial>
        <mass value="${mass3}" />
        <origin xyz="0.03443 0 0.00018" rpy="0 0 0"/>
        <inertia ixx="0.00003095696" ixy="0.00000000169" ixz="0" iyy="0.00016728462" iyz="0" izz="0.00015971261"/>
      </inertial>

      <visual>
        <origin xyz="0 0 0" rpy="0 ${pi / 2} ${-pi / 2}" />
        <geometry>
          <mesh filename="package://aerial_manipulators/meshes/wp_manipulator/link3.dae"
            scale="1 1 1" />
        </geometry>
      </visual>
    </link>



    <link name='link4'>
      <inertial>
        <mass value="${mass4}" />
        <origin xyz="0.03624 0 -0.00059" rpy="0 0 0"/>
        <inertia ixx="0.00000540203" ixy="0" ixz="0" iyy="0.00001225566" iyz="0" izz="0.00000858285"/>
      </inertial>

      <visual>
        <origin xyz="0 0 0" rpy="0 ${pi / 2} -${pi / 2}" />
        <geometry>
          <mesh filename="package://aerial_manipulators/meshes/wp_manipulator/link4.dae"
            scale="1 1 1" />
        </geometry>
      </visual>
    </link>



    <link name='link5'>
      <inertial>
        <mass value="${mass5}" />
        <origin xyz="0.01179 0 0.00023" rpy="0 0 0"/>
        <inertia ixx="0.00001323215" ixy="0.00000000037" ixz="-0.0000019846" iyy="0.00002293047" iyz="0.0000000002" izz="0.00002030725"/>
      </inertial>

      <visual>
        <origin xyz="0 0 0" rpy="0 ${pi / 2} 0" />
        <geometry>
          <mesh filename="package://aerial_manipulators/meshes/wp_manipulator/link5.dae"
            scale="1 1 1" />
        </geometry>
      </visual>

      <collision>
        <origin xyz="0 0 0" rpy="0 ${pi / 2} 0" />
        <geometry>
          <mesh filename="package://aerial_manipulators/meshes/wp_manipulator/link5.dae"
            scale="1 1 1" />
        </geometry>
      </collision>
    </link>

<!--
    <link name="endEffector">
      <inertial>
        <mass value="0.00001" />
        <origin xyz="0 0 0" rpy="0 0 0"/>
        <inertia
          ixx="0.00001" ixy="0" ixz="0"
          iyx="0" iyy="0.00001" iyz="0"
          izx="0" izy="0" izz="0.00001"/>
      </inertial>

      <visual>
        <geometry>
          <sphere radius="0.005"/>
        </geometry>
      </visual>
    </link>
-->




    <joint name="link0_to_link1" type="revolute">
      <parent link="${parent}"/>
      <child link="link1"/>
      <!-- Adjust Gazebo coordinate system to link1 coordinate system -->
      <!--origin xyz="0 0 0.075" rpy="${pi/2} 0 ${pi}"/-->
      <xacro:insert_block name="origin"/>
      <limit upper="1.57" lower="-1.57" effort="10000000" velocity="20"/>
      <axis xyz="0 0 1" />
    </joint>



    <joint name="link1_to_link2" type="revolute">
      <parent link="link1"/>
      <child link="link2"/>
      <origin xyz="0 ${a1} 0" rpy="0 0 ${theta1}"/>
      <limit upper="2.2" lower="-2.2" effort="10000000" velocity="20"/>
      <axis xyz="0 0 1" />
    </joint>



    <joint name="link2_to_link3" type="revolute">
      <parent link="link2"/>
      <child link="link3"/>
      <origin xyz="${a2} 0 0" rpy="${alpha2} 0 0"/>
      <limit upper="1.57" lower="-1.57" effort="10000000" velocity="20"/>
      <axis xyz="0 0 1" />
    </joint>


    <joint name="link3_to_link4" type="revolute">
      <parent link="link3"/>
      <child link="link4"/>
      <origin xyz="${a3} 0 0" rpy="0 0 0"/>
      <limit upper="1.57" lower="-1.57" effort="10000000" velocity="20"/>
      <axis xyz="0 0 1" />
    </joint>
<!-- <limit upper="1.57" lower="-1.57" effort="10000000" velocity="20"/> -->


    <joint name="link4_to_link5" type="revolute">
      <parent link="link4"/>
      <child link="link5"/>
      <origin xyz="${a4} 0 0" rpy="0 0 0"/>
      <limit upper="2.3" lower="-2.3" effort="10000000" velocity="20"/>
      <axis xyz="0 0 1" />
    </joint>
<!--       <limit upper="2.3" lower="-2.3" effort="10000000" velocity="20"/> -->
<!--
    <joint name="link5_to_ef" type="revolute">
      <parent link="link5"/>
      <child link="endEffector"/>
      <origin xyz="${d5} 0 0" rpy="${-pi/2} 0 ${-pi/2}"/>
      <limit upper="0" lower="0" effort="10000000" velocity="20"/>
      <axis xyz="0 0 1" />
    </joint>
-->
  </xacro:macro>



  <!-- We add a <transmission> block for every joint that we wish to actuate. -->
  <xacro:macro name="transmisija" params="trans_number joint_name">
    <transmission name="transmission_${trans_number}">
      <type>transmission_interface/SimpleTransmission</type>
      <joint name="${joint_name}">
        <hardwareInterface>hardware_interface/EffortJointInterface</hardwareInterface>
      </joint>
      <actuator name="motor_${trans_number}">
        <hardwareInterface>hardware_interface/EffortActuatorInterface</hardwareInterface>
        <mechanicalReduction>1</mechanicalReduction>
      </actuator>
    </transmission>
  </xacro:macro>


  <xacro:macro name="force_sensor"
      params="*origin">
__________________________-->
      <!--LINK1 force sensor stand-->
      <!--_____________________________________________________________-->
      <link name='link_force_sensor_stand'>

        <inertial>
          <mass value="0.002" />
          <origin rpy="0 0 0" xyz="0 0.46818651 0"/>
          <inertia
            ixx="0.00023434322" ixy="0" ixz="0.0"
            iyx="0" iyy="0.00001547123" iyz="0"
            izx="0.0" izy="0" izz="0.00023434322"/>
        </inertial>

        <visual>
          <origin xyz="0 0 0" rpy="0 0 0" />
          <geometry>
            <mesh filename="package://aerial_manipulators/meshes/wp_manipulator/forcesensor_stand.dae"
              scale="0.1 0.1 0.1" />
          </geometry>
        </visual>

        <!--collision name='collision'>
          <origin xyz="0 0 0" rpy="0 0 0"/>
          <geometry>
            <mesh filename="package://mmuav_description/meshes/forcesensor_stand.dae"
              scale="1 1 1" />
          </geometry>
        </collision-->
      </link>
      <!--_____________________________________________________________-->
      <!--LINK2 force sensor mount bottom-->
      <!--_____________________________________________________________-->
      <link name='link_force_sensor_bottom_mount'>

        <inertial>
          <mass value="0.0005" />
          <origin rpy="0 0 0" xyz="0.0 0.000206111 0.0"/>
          <inertia
            ixx="0.0000002139" ixy="0" ixz="0.0"
            iyx="0" iyy="0.0000004241" iyz="0"
            izx="0.0" izy="0" izz="0.0000002139"/>
        </inertial>

        <visual>
          <origin xyz="0 0 0" rpy="0 0 0" />
          <geometry>
            <mesh filename="package://aerial_manipulators/meshes/wp_manipulator/forcesensor_mount_bottom.dae"
              scale="0.1 0.1 0.1" />
          </geometry>
        </visual>

        <!--collision name='collision'>
          <origin xyz="0 0 0" rpy="0 0 0"/>
          <geometry>
            <mesh filename="package://mmuav_description/meshes/forcesensor_mount_bottom.dae"
              scale="1 1 1" />
          </geometry>
        </collision-->
      </link>
      <!--_____________________________________________________________-->
      <!--LINK2 force sensor mount top-->
      <!--_____________________________________________________________-->
      <link name='link_force_sensor_top_mount'>

        <inertial>
          <mass value="0.00080" />
          <origin rpy="0 0 0" xyz="0 0 -0.02998408"/>
          <inertia
            ixx="0.0000059994" ixy="0" ixz="0.0"
            iyx="0" iyy="0.0000059994" iyz="0"
            izx="0.0" izy="0" izz="0.0000119615"/>
        </inertial>

        <!--0.01903151 0.01661061 0.02154592-->

        <visual>
          <origin xyz="-0.001903 -0.001661 -0.005153" rpy="0 0 0" />
          <geometry>
            <mesh filename="package://aerial_manipulators/meshes/wp_manipulator/forcesensor_mount_top.dae"
              scale="0.1 0.1 0.1" />
          </geometry>
        </visual>

        <collision name='collision'>
          <origin xyz="-0.001903 -0.001661 -0.005153" rpy="0 0 0"/>
          <geometry>
            <mesh filename="package://aerial_manipulators/meshes/wp_manipulator/forcesensor_mount_top.dae"
              scale="0.1 0.1 0.1" />
          </geometry>
        </collision>
      </link>

      <!--_____________________________________________________________-->
      <!--JOINT1 FIXED force_sensor_stand-->
      <!--_____________________________________________________________-->
      <joint name="joint_force_sensor_stand" type="fixed">
          <xacro:insert_block name="origin"/>
          <parent link="link5"/>
          <child link="link_force_sensor_stand"/>
      </joint>
      <!--_____________________________________________________________-->
      <!--JOINT2 FIXED joint_force_sensor_mount_bottom-->
      <!--_____________________________________________________________-->
      <joint name="joint_force_sensor_mount_bottom" type="fixed">
          <origin xyz="0 0.1003 0" rpy="${pi} 0 0" />
          <parent link="link_force_sensor_stand"/>
          <child link="link_force_sensor_bottom_mount"/>
      </joint>
      <!--_____________________________________________________________-->
      <!--JOINT2 FIXED force_sensor_mount_top-->
      <!--_____________________________________________________________-->
      <joint name="joint_force_sensor_mount_top" type="prismatic">
          <origin xyz="0 0 0" rpy="${-pi/2} 0 0" />
          <parent link="link_force_sensor_bottom_mount"/>
          <child link="link_force_sensor_top_mount"/>
          <axis xyz="0 0 1" />
          <limit effort="0" velocity="0" lower="0" upper="0" />
      </joint>
    </xacro:macro>


</robot>
